<?xml version="1.0" ?>
<!-- =================================================================================== -->
<!-- |    This document was autogenerated by xacro from bob_joints.xacro               | -->
<!-- |    EDITING THIS FILE BY HAND IS NOT RECOMMENDED                                 | -->
<!-- =================================================================================== -->
<robot name="bob_joints">
    <link name="world"/>
  <joint name="joint_w" type="fixed">
    <parent link="world"/>
    <child link="base_link"/>
  </joint>
  <material name="silver">
    <color rgba="0.700 0.700 0.700 1.000"/>
  </material>
  <transmission name="limb1_to_base_link_tran">
    <type>transmission_interface/SimpleTransmission</type>
    <joint name="limb1_to_base_link">
      <hardwareInterface>hardware_interface/EffortJointInterface</hardwareInterface>
    </joint>
    <actuator name="limb1_to_base_link_actr">
      <hardwareInterface>hardware_interface/EffortJointInterface</hardwareInterface>
      <mechanicalReduction>1</mechanicalReduction>
    </actuator>
  </transmission>
  <transmission name="limb2_to_limb1_tran">
    <type>transmission_interface/SimpleTransmission</type>
    <joint name="limb2_to_limb1">
      <hardwareInterface>hardware_interface/EffortJointInterface</hardwareInterface>
    </joint>
    <actuator name="limb2_to_limb1_actr">
      <hardwareInterface>hardware_interface/EffortJointInterface</hardwareInterface>
      <mechanicalReduction>1</mechanicalReduction>
    </actuator>
  </transmission>
  <transmission name="limb3_to_limb2_tran">
    <type>transmission_interface/SimpleTransmission</type>
    <joint name="limb3_to_limb2">
      <hardwareInterface>hardware_interface/EffortJointInterface</hardwareInterface>
    </joint>
    <actuator name="limb3_to_limb2_actr">
      <hardwareInterface>hardware_interface/EffortJointInterface</hardwareInterface>
      <mechanicalReduction>1</mechanicalReduction>
    </actuator>
  </transmission>
  <transmission name="limb4_to_limb3_tran">
    <type>transmission_interface/SimpleTransmission</type>
    <joint name="limb4_to_limb3">
      <hardwareInterface>hardware_interface/EffortJointInterface</hardwareInterface>
    </joint>
    <actuator name="limb4_to_limb3_actr">
      <hardwareInterface>hardware_interface/EffortJointInterface</hardwareInterface>
      <mechanicalReduction>1</mechanicalReduction>
    </actuator>
  </transmission>
  <transmission name="brush_to_limb4_tran">
    <type>transmission_interface/SimpleTransmission</type>
    <joint name="brush_to_limb4">
      <hardwareInterface>hardware_interface/EffortJointInterface</hardwareInterface>
    </joint>
    <actuator name="brush_to_limb4_actr">
      <hardwareInterface>hardware_interface/EffortJointInterface</hardwareInterface>
      <mechanicalReduction>1</mechanicalReduction>
    </actuator>
  </transmission>
  <gazebo>
    <plugin filename="libgazebo_ros_control.so" name="control"/>
  </gazebo>
  <gazebo reference="base_link">
    <material>Gazebo/Silver</material>
    <mu1>0.2</mu1>
    <mu2>0.2</mu2>
    <self_collide>true</self_collide>
    <gravity>true</gravity>
  </gazebo>
  <gazebo reference="limb1_1">
    <material>Gazebo/Silver</material>
    <mu1>0.2</mu1>
    <mu2>0.2</mu2>
    <self_collide>true</self_collide>
  </gazebo>
  <gazebo reference="limb2_1">
    <material>Gazebo/Silver</material>
    <mu1>0.2</mu1>
    <mu2>0.2</mu2>
    <self_collide>true</self_collide>
  </gazebo>
  <gazebo reference="limb3_1">
    <material>Gazebo/Silver</material>
    <mu1>0.2</mu1>
    <mu2>0.2</mu2>
    <self_collide>true</self_collide>
  </gazebo>
  <gazebo reference="limb4_1">
    <material>Gazebo/Silver</material>
    <mu1>0.2</mu1>
    <mu2>0.2</mu2>
    <self_collide>true</self_collide>
  </gazebo>
  <gazebo reference="brush_1">
    <material>Gazebo/Silver</material>
    <mu1>0.2</mu1>
    <mu2>0.2</mu2>
    <self_collide>true</self_collide>
  </gazebo>
  <link name="base_link">
    <inertial>
      <origin rpy="0 0 0" xyz="0.0006803142090778661 -0.010329455009390021 0.03163382570046437"/>
      <mass value="1.9193144626991494"/>
      <inertia ixx="0.001607" ixy="2e-06" ixz="0.0" iyy="0.001953" iyz="2.2e-05" izz="0.002773"/>
    </inertial>
    <visual>
      <origin rpy="0 0 0" xyz="0 0 0"/>
      <geometry>
        <mesh filename="file:///home/space/ws_moveit/install/bob_joints_description/share/bob_joints_description/meshes/base_link.stl" scale="1 1 1"/>
      </geometry>
      <material name="silver"/>
    </visual>
    <collision>
      <origin rpy="0 0 0" xyz="0 0 0"/>
      <geometry>
        <mesh filename="file:///home/space/ws_moveit/install/bob_joints_description/share/bob_joints_description/meshes/base_link.stl" scale="1 1 1"/>
      </geometry>
    </collision>
  </link>
  <link name="limb1_1">
    <inertial>
      <origin rpy="0 0 0" xyz="-3.974717860263195e-05 6.12616581656053e-07 0.017126004805338477"/>
      <mass value="1.206894590873129"/>
      <inertia ixx="0.001242" ixy="0.0" ixz="3e-06" iyy="0.001509" iyz="-0.0" izz="0.001729"/>
    </inertial>
    <visual>
      <origin rpy="0 0 0" xyz="-0.000497 0.010142 -0.055856"/>
      <geometry>
        <mesh filename="file:///home/space/ws_moveit/install/bob_joints_description/share/bob_joints_description/meshes/limb1_1.stl" scale="1 1 1"/>
      </geometry>
      <material name="silver"/>
    </visual>
    <collision>
      <origin rpy="0 0 0" xyz="-0.000497 0.010142 -0.055856"/>
      <geometry>
        <mesh filename="file:///home/space/ws_moveit/install/bob_joints_description/share/bob_joints_description/meshes/limb1_1.stl" scale="1 1 1"/>
      </geometry>
    </collision>
  </link>
  <link name="limb2_1">
    <inertial>
      <origin rpy="0 0 0" xyz="0.027279852822002917 0.0016072156717585832 0.04366871261710806"/>
      <mass value="0.6598236151248956"/>
      <inertia ixx="0.000974" ixy="-5e-06" ixz="-3.9e-05" iyy="0.00133" iyz="3.5e-05" izz="0.000473"/>
    </inertial>
    <visual>
      <origin rpy="0 0 0" xyz="0.028822 0.010141 -0.13477"/>
      <geometry>
        <mesh filename="file:///home/space/ws_moveit/install/bob_joints_description/share/bob_joints_description/meshes/limb2_1.stl" scale="1 1 1"/>
      </geometry>
      <material name="silver"/>
    </visual>
    <collision>
      <origin rpy="0 0 0" xyz="0.028822 0.010141 -0.13477"/>
      <geometry>
        <mesh filename="file:///home/space/ws_moveit/install/bob_joints_description/share/bob_joints_description/meshes/limb2_1.stl" scale="1 1 1"/>
      </geometry>
    </collision>
  </link>
  <link name="limb3_1">
    <inertial>
      <origin rpy="0 0 0" xyz="0.025873636316636188 0.0025217337529823743 0.023834763710508522"/>
      <mass value="0.4130666909549956"/>
      <inertia ixx="0.000409" ixy="-7e-06" ixz="-1.1e-05" iyy="0.000523" iyz="1.5e-05" izz="0.000188"/>
    </inertial>
    <visual>
      <origin rpy="0 0 0" xyz="0.028822 0.010141 -0.242983"/>
      <geometry>
        <mesh filename="file:///home/space/ws_moveit/install/bob_joints_description/share/bob_joints_description/meshes/limb3_1.stl" scale="1 1 1"/>
      </geometry>
      <material name="silver"/>
    </visual>
    <collision>
      <origin rpy="0 0 0" xyz="0.028822 0.010141 -0.242983"/>
      <geometry>
        <mesh filename="file:///home/space/ws_moveit/install/bob_joints_description/share/bob_joints_description/meshes/limb3_1.stl" scale="1 1 1"/>
      </geometry>
    </collision>
  </link>
  <link name="limb4_1">
    <inertial>
      <origin rpy="0 0 0" xyz="0.028342681879727424 -1.4410099062663745e-05 0.023522306875613797"/>
      <mass value="0.14026966150600653"/>
      <inertia ixx="5.3e-05" ixy="0.0" ixz="-6e-06" iyy="0.0001" iyz="0.0" izz="6.1e-05"/>
    </inertial>
    <visual>
      <origin rpy="0 0 0" xyz="0.009632 0.010611 -0.31044"/>
      <geometry>
        <mesh filename="file:///home/space/ws_moveit/install/bob_joints_description/share/bob_joints_description/meshes/limb4_1.stl" scale="1 1 1"/>
      </geometry>
      <material name="silver"/>
    </visual>
    <collision>
      <origin rpy="0 0 0" xyz="0.009632 0.010611 -0.31044"/>
      <geometry>
        <mesh filename="file:///home/space/ws_moveit/install/bob_joints_description/share/bob_joints_description/meshes/limb4_1.stl" scale="1 1 1"/>
      </geometry>
    </collision>
  </link>
  <link name="brush_1">
    <inertial>
      <origin rpy="0 0 0" xyz="4.3052581448488336e-07 3.897601171289067e-07 0.0050003780918617124"/>
      <mass value="0.0026048711836780623"/>
      <inertia ixx="0.0" ixy="0.0" ixz="0.0" iyy="0.0" iyz="-0.0" izz="0.0"/>
    </inertial>
    <visual>
      <origin rpy="0 0 0" xyz="-0.042646 0.010713 -0.39867"/>
      <geometry>
        <mesh filename="file:///home/space/ws_moveit/install/bob_joints_description/share/bob_joints_description/meshes/brush_1.stl" scale="1 1 1"/>
      </geometry>
      <material name="silver"/>
    </visual>
    <collision>
      <origin rpy="0 0 0" xyz="-0.042646 0.010713 -0.39867"/>
      <geometry>
        <mesh filename="file:///home/space/ws_moveit/install/bob_joints_description/share/bob_joints_description/meshes/brush_1.stl" scale="1 1 1"/>
      </geometry>
    </collision>
  </link>
<joint name="limb1_to_base_link" type="revolute">
    <origin rpy="0 0 0" xyz="0.000497 -0.010142 0.055856"/>
    <parent link="base_link"/>
    <child link="limb1_1"/>
    <axis xyz="-0.0 0.0 1.0"/>
    <limit lower="-1.5708" upper="1.5708" effort="100" velocity="1"/>
  </joint>

  <joint name="limb2_to_limb1" type="revolute">
    <origin rpy="0 0 0" xyz="-0.029319 1e-06 0.078914"/>
    <parent link="limb1_1"/>
    <child link="limb2_1"/>
    <axis xyz="1.0 0.0 -0.0"/>
    <limit lower="-1.5708" upper="1.5708" effort="100" velocity="1"/>
  </joint>

  <joint name="limb3_to_limb2" type="revolute">
    <origin rpy="0 0 0" xyz="0.0 0.0 0.108213"/>
    <parent link="limb2_1"/>
    <child link="limb3_1"/>
    <axis xyz="1.0 0.0 0.0"/>
    <limit lower="-2.3562" upper="0.7854" effort="100" velocity="1"/>
  </joint>

  <joint name="limb4_to_limb3" type="revolute">
    <origin rpy="0 0 0" xyz="0.01919 -0.00047 0.067457"/>
    <parent link="limb3_1"/>
    <child link="limb4_1"/>
    <axis xyz="-1.0 -0.0 -0.0"/>
    <limit lower="-1.5708" upper="1.5708" effort="100" velocity="1"/>
  </joint>

  <joint name="brush_to_limb4" type="fixed">
    <origin rpy="0 0 0" xyz="0.052278 -0.000102 0.08823"/>
    <parent link="limb4_1"/>
    <child link="brush_1"/>
    <axis xyz="-0.0 0.0 1.0"/>
  </joint>
</robot>
