<?xml version="1.0" ?>
<robot name="bob_joints" xmlns:xacro="http://www.ros.org/wiki/xacro">

<xacro:include filename="$(find bob_joints_description)/urdf/materials.xacro" />
<xacro:include filename="$(find bob_joints_description)/urdf/bob_joints.trans" />
<xacro:include filename="$(find bob_joints_description)/urdf/bob_joints.gazebo" />
<link name="base_link">
  <inertial>
    <origin xyz="0.0006803142090778661 -0.010329455009390021 0.03163382570046437" rpy="0 0 0"/>
    <mass value="1.9193144626991494"/>
    <inertia ixx="0.001607" iyy="0.001953" izz="0.002773" ixy="2e-06" iyz="2.2e-05" ixz="0.0"/>
  </inertial>
  <visual>
    <origin xyz="0 0 0" rpy="0 0 0"/>
    <geometry>
      <mesh filename="file://$(find bob_joints_description)/meshes/base_link.stl" scale="1 1 1"/>
    </geometry>
    <material name="silver"/>
  </visual>
  <collision>
    <origin xyz="0 0 0" rpy="0 0 0"/>
    <geometry>
      <mesh filename="file://$(find bob_joints_description)/meshes/base_link.stl" scale="1 1 1"/>
    </geometry>
  </collision>
</link>

<link name="limb1_1">
  <inertial>
    <origin xyz="-3.974717860263195e-05 6.12616581656053e-07 0.017126004805338477" rpy="0 0 0"/>
    <mass value="1.206894590873129"/>
    <inertia ixx="0.001242" iyy="0.001509" izz="0.001729" ixy="0.0" iyz="-0.0" ixz="3e-06"/>
  </inertial>
  <visual>
    <origin xyz="-0.000497 0.010142 -0.055856" rpy="0 0 0"/>
    <geometry>
      <mesh filename="file://$(find bob_joints_description)/meshes/limb1_1.stl" scale="1 1 1"/>
    </geometry>
    <material name="silver"/>
  </visual>
  <collision>
    <origin xyz="-0.000497 0.010142 -0.055856" rpy="0 0 0"/>
    <geometry>
      <mesh filename="file://$(find bob_joints_description)/meshes/limb1_1.stl" scale="1 1 1"/>
    </geometry>
  </collision>
</link>

<link name="limb2_1">
  <inertial>
    <origin xyz="0.027279852822002917 0.0016072156717585832 0.04366871261710806" rpy="0 0 0"/>
    <mass value="0.6598236151248956"/>
    <inertia ixx="0.000974" iyy="0.00133" izz="0.000473" ixy="-5e-06" iyz="3.5e-05" ixz="-3.9e-05"/>
  </inertial>
  <visual>
    <origin xyz="0.028822 0.010141 -0.13477" rpy="0 0 0"/>
    <geometry>
      <mesh filename="file://$(find bob_joints_description)/meshes/limb2_1.stl" scale="1 1 1"/>
    </geometry>
    <material name="silver"/>
  </visual>
  <collision>
    <origin xyz="0.028822 0.010141 -0.13477" rpy="0 0 0"/>
    <geometry>
      <mesh filename="file://$(find bob_joints_description)/meshes/limb2_1.stl" scale="1 1 1"/>
    </geometry>
  </collision>
</link>

<link name="limb3_1">
  <inertial>
    <origin xyz="0.025873636316636188 0.0025217337529823743 0.023834763710508522" rpy="0 0 0"/>
    <mass value="0.4130666909549956"/>
    <inertia ixx="0.000409" iyy="0.000523" izz="0.000188" ixy="-7e-06" iyz="1.5e-05" ixz="-1.1e-05"/>
  </inertial>
  <visual>
    <origin xyz="0.028822 0.010141 -0.242983" rpy="0 0 0"/>
    <geometry>
      <mesh filename="file://$(find bob_joints_description)/meshes/limb3_1.stl" scale="1 1 1"/>
    </geometry>
    <material name="silver"/>
  </visual>
  <collision>
    <origin xyz="0.028822 0.010141 -0.242983" rpy="0 0 0"/>
    <geometry>
      <mesh filename="file://$(find bob_joints_description)/meshes/limb3_1.stl" scale="1 1 1"/>
    </geometry>
  </collision>
</link>

<link name="limb4_1">
  <inertial>
    <origin xyz="0.028342681879727424 -1.4410099062663745e-05 0.023522306875613797" rpy="0 0 0"/>
    <mass value="0.14026966150600653"/>
    <inertia ixx="5.3e-05" iyy="0.0001" izz="6.1e-05" ixy="0.0" iyz="0.0" ixz="-6e-06"/>
  </inertial>
  <visual>
    <origin xyz="0.009632 0.010611 -0.31044" rpy="0 0 0"/>
    <geometry>
      <mesh filename="file://$(find bob_joints_description)/meshes/limb4_1.stl" scale="1 1 1"/>
    </geometry>
    <material name="silver"/>
  </visual>
  <collision>
    <origin xyz="0.009632 0.010611 -0.31044" rpy="0 0 0"/>
    <geometry>
      <mesh filename="file://$(find bob_joints_description)/meshes/limb4_1.stl" scale="1 1 1"/>
    </geometry>
  </collision>
</link>

<link name="brush_1">
  <inertial>
    <origin xyz="4.3052581448488336e-07 3.897601171289067e-07 0.0050003780918617124" rpy="0 0 0"/>
    <mass value="0.0026048711836780623"/>
    <inertia ixx="0.0" iyy="0.0" izz="0.0" ixy="0.0" iyz="-0.0" ixz="0.0"/>
  </inertial>
  <visual>
    <origin xyz="-0.042646 0.010713 -0.39867" rpy="0 0 0"/>
    <geometry>
      <mesh filename="file://$(find bob_joints_description)/meshes/brush_1.stl" scale="1 1 1"/>
    </geometry>
    <material name="silver"/>
  </visual>
  <collision>
    <origin xyz="-0.042646 0.010713 -0.39867" rpy="0 0 0"/>
    <geometry>
      <mesh filename="file://$(find bob_joints_description)/meshes/brush_1.stl" scale="1 1 1"/>
    </geometry>
  </collision>
</link>

<joint name="limb1_to_base_link" type="continuous">
  <origin xyz="0.000497 -0.010142 0.055856" rpy="0 0 0"/>
  <parent link="base_link"/>
  <child link="limb1_1"/>
  <axis xyz="-0.0 0.0 1.0"/>
</joint>

<joint name="limb2_to_limb1" type="continuous">
  <origin xyz="-0.029319 1e-06 0.078914" rpy="0 0 0"/>
  <parent link="limb1_1"/>
  <child link="limb2_1"/>
  <axis xyz="1.0 0.0 -0.0"/>
</joint>

<joint name="limb3_to_limb2" type="continuous">
  <origin xyz="0.0 0.0 0.108213" rpy="0 0 0"/>
  <parent link="limb2_1"/>
  <child link="limb3_1"/>
  <axis xyz="1.0 0.0 0.0"/>
</joint>

<joint name="limb4_to_limb3" type="continuous">
  <origin xyz="0.01919 -0.00047 0.067457" rpy="0 0 0"/>
  <parent link="limb3_1"/>
  <child link="limb4_1"/>
  <axis xyz="-1.0 -0.0 -0.0"/>
</joint>

<joint name="brush_to_limb4" type="continuous">
  <origin xyz="0.052278 -0.000102 0.08823" rpy="0 0 0"/>
  <parent link="limb4_1"/>
  <child link="brush_1"/>
  <axis xyz="-0.0 0.0 1.0"/>
</joint>

</robot>
